Traceback (most recent call last):
  File "<pyshell#102>", line 2, in <module>
Exception: this is the error
